<?xml version="1.0" ?>
<robot name="typhoon_h480">
  <joint name="typhoon_h480__cgo3_mount_joint" type="fixed">
    <parent link="base_link"/>
    <child link="typhoon_h480__cgo3_mount_link"/>
    <origin xyz="0   0   0.26" rpy="0 0 0"/>
    <axis xyz="0 0 1"/>
    <limit lower="0.0" upper="0.0" effort="100.0" velocity="-1.0"/>
  </joint>
  <joint name="typhoon_h480__cgo3_vertical_arm_joint" type="revolute"> 
    <parent link="typhoon_h480__cgo3_mount_link"/>
    <child link="typhoon_h480__cgo3_vertical_arm_link"/>
    <origin xyz="-0.026  0    -0.1" rpy="0 0 0"/>
    <axis xyz="0 0 1"/>
    <limit lower="-1e+16" upper="1e+16" effort="100.0" velocity="-1.0"/>
  </joint>
  <joint name="typhoon_h480__cgo3_horizontal_arm_joint" type="revolute">
    <parent link="typhoon_h480__cgo3_vertical_arm_link"/>
    <child link="typhoon_h480__cgo3_horizontal_arm_link"/>
    <origin xyz="-0.044  0    -0.062" rpy="0 0 0"/>
    <axis xyz="-1  0  0"/>
    <limit lower="-0.785398" upper="0.785398" effort="100.0" velocity="-1.0"/>
  </joint>
  <joint name="typhoon_h480__cgo3_camera_joint" type="revolute">
    <parent link="typhoon_h480__cgo3_horizontal_arm_link"/>
    <child link="camera_link"/>
    <origin xyz="0.06 0.03 0" rpy="0 0 0"/>
    <axis xyz="0 -1  0"/>
    <limit lower="-1.5708" upper="0.7854" effort="100.0" velocity="-1.0"/>
  </joint>
  <joint name="typhoon_h480__left_leg_joint" type="revolute">
    <parent link="base_link"/>
    <child link="typhoon_h480__left_leg"/>
    <origin xyz="0.00025 -0.04051  0.212" rpy="0 0 0"/>
    <axis xyz="-1  0  0"/>
    <limit lower="0.0" upper="1.0" effort="100.0" velocity="-1.0"/>
  </joint>
  <joint name="typhoon_h480__right_leg_joint" type="revolute">
    <parent link="base_link"/>
    <child link="typhoon_h480__right_leg"/>
    <origin xyz="0.00025 0.04051 0.212" rpy="0 0 0"/>
    <axis xyz="1 0 0"/>
    <limit lower="0.0" upper="1.0" effort="100.0" velocity="-1.0"/>
  </joint>
  <joint name="typhoon_h480__typhoon_h480/imu_joint" type="fixed">
    <parent link="base_link"/>
    <child link="imu_link"/>
    <origin xyz="0   0   0.26" rpy="0 0 0"/>
    <axis xyz="1 0 0"/>
    <limit lower="0.0" upper="0.0" effort="0.0" velocity="0.0"/>
  </joint>
  <joint name="typhoon_h480__lidar_joint" type="fixed">
    <parent link="base_link"/>
    <child link="lidar_link"/>
    <origin xyz="0   0   0.26" rpy="0 0 0"/>
    <axis xyz="0 0 0"/>
    <limit lower="0" upper="0" effort="0" velocity="0"/>
  </joint>
  <joint name="typhoon_h480__gps_joint" type="fixed">
    <parent link="base_link"/>
    <child link="gps_link"/>
    <origin xyz="0   0   0.26" rpy="0 0 0"/>
    <axis xyz="0 0 0"/>
    <limit lower="0" upper="0" effort="0" velocity="0"/>
  </joint>
  <joint name="typhoon_h480__rotor_3_joint" type="revolute">
    <parent link="base_link"/>
    <child link="typhoon_h480__rotor_3"/>
    <origin xyz="0.21139 0.11976 0.34221" rpy="0 0 0"/>
    <axis xyz="0 0 1"/>
    <limit lower="-1e+16" upper="1e+16" effort="10.0" velocity="-1.0"/>
  </joint>
  <joint name="typhoon_h480__rotor_0_joint" type="revolute">
    <parent link="base_link"/>
    <child link="typhoon_h480__rotor_0"/>
    <origin xyz="-0.20939  0.12276  0.34221" rpy="0      0      2.09439"/>
    <axis xyz="0 0 1"/>
    <limit lower="-1e+16" upper="1e+16" effort="10.0" velocity="-1.0"/>
  </joint>
  <joint name="typhoon_h480__rotor_4_joint" type="revolute">
    <parent link="base_link"/>
    <child link="typhoon_h480__rotor_4"/>
    <origin xyz="-0.00187  0.2427   0.34221" rpy="0 0 0"/>
    <axis xyz="0 0 1"/>
    <limit lower="-1e+16" upper="1e+16" effort="10.0" velocity="-1.0"/>
  </joint>
  <joint name="typhoon_h480__rotor_1_joint" type="revolute">
    <parent link="base_link"/>
    <child link="typhoon_h480__rotor_1"/>
    <origin xyz="0.21139 -0.11976  0.34221" rpy="0       0      -2.09439"/>
    <axis xyz="0 0 1"/>
    <limit lower="-1e+16" upper="1e+16" effort="10.0" velocity="-1.0"/>
  </joint>
  <joint name="typhoon_h480__rotor_5_joint" type="revolute">
    <parent link="base_link"/>
    <child link="typhoon_h480__rotor_5"/>
    <origin xyz="-0.00187 -0.2427   0.34221" rpy="0       0      -2.09439"/>
    <axis xyz="0 0 1"/>
    <limit lower="-1e+16" upper="1e+16" effort="10.0" velocity="-1.0"/>
  </joint>
  <joint name="typhoon_h480__rotor_2_joint" type="revolute">
    <parent link="base_link"/>
    <child link="typhoon_h480__rotor_2"/>
    <origin xyz="-0.20939 -0.12276  0.34221" rpy="0      0      2.09439"/>
    <axis xyz="0 0 1"/>
    <limit lower="-1e+16" upper="1e+16" effort="10.0" velocity="-1.0"/>
  </joint>
  <link name="base_link">
    <inertial>
      <mass value="2.02"/>
      <origin xyz="0.001  0    -0.009" rpy="0 0 0"/>
      <inertia ixx="0.011" ixy="0" ixz="0" iyy="0.015" iyz="0" izz="0.021"/>
    </inertial>
    <collision name="base_link_collision">
      <origin xyz="0   0   0.26" rpy="0 0 0"/>
      <geometry>
        <box size="0.67 0.67 0.15"/>
      </geometry>
    </collision>
    <visual name="base_link_visual">
      <origin xyz="0   0   0.26" rpy="0      0      3.14159"/>
      <geometry>
        <mesh filename="package://drone_nav/description/meshes/main_body_remeshed_v3.stl" scale="0.001 0.001 0.001"/>
      </geometry>
    </visual>
  </link>
  <link name="typhoon_h480__cgo3_mount_link">
    <inertial>
      <mass value="0.1"/>
      <origin xyz="-0.041  0    -0.162" rpy="0 0 0"/>
      <inertia ixx="0.001" ixy="0" ixz="0" iyy="0.001" iyz="0" izz="0.001"/>
    </inertial>
    <visual name="typhoon_h480__cgo3_mount_visual">
      <origin xyz="0 0 0" rpy="0 0 0"/>
      <geometry>
        <mesh filename="package://drone_nav/description/meshes/cgo3_mount_remeshed_v1.stl" scale="0.001 0.001 0.001"/>
      </geometry>
    </visual>
  </link>
  <link name="typhoon_h480__cgo3_vertical_arm_link">
    <inertial>
      <mass value="0.1"/>
      <origin xyz="-0.041  0    -0.162" rpy="0 0 0"/>
      <inertia ixx="0.001" ixy="0" ixz="0" iyy="0.001" iyz="0" izz="0.001"/>
    </inertial>
    <visual name="typhoon_h480__cgo3_vertical_arm_visual">
      <origin xyz="-0.025  0     0.1" rpy="0      0      3.14159"/>
      <geometry>
        <mesh filename="package://drone_nav/description/meshes/cgo3_vertical_arm_remeshed_v1.stl" scale="0.001 0.001 0.001"/>
      </geometry>
    </visual>
  </link>
  <link name="typhoon_h480__cgo3_horizontal_arm_link">
    <inertial>
      <mass value="0.1"/>
      <origin xyz="-0.041  0    -0.081" rpy="0 0 0"/>
      <inertia ixx="0.001" ixy="0" ixz="0" iyy="0.001" iyz="0" izz="0.001"/>
    </inertial>
    <visual name="typhoon_h480__cgo3_horizontal_arm_visual">
      <origin xyz="0.02  0    0.162" rpy="0      0      3.14159"/>
      <geometry>
        <mesh filename="package://drone_nav/description/meshes/cgo3_horizontal_arm_remeshed_v1.stl" scale="0.001 0.001 0.001"/>
      </geometry>
    </visual>
  </link>
  <link name="camera_link">
    <inertial>
      <mass value="0.1"/>
      <origin xyz="-0.041  0    -0.162" rpy="0 0 0"/>
      <inertia ixx="0.001" ixy="0" ixz="0" iyy="0.001" iyz="0" izz="0.001"/>
    </inertial>
    <collision name="typhoon_h480__cgo3_camera_collision">
      <origin xyz="-0.031 -0.03   0" rpy="0 0 0"/>
      <geometry>
        <sphere radius="0.035"/>
      </geometry>
    </collision>
    <visual name="typhoon_h480__cgo3_camera_visual">
      <origin xyz="-0.04  -0.03   0.162" rpy="0      0      3.14159"/>
      <geometry>
        <mesh filename="package://drone_nav/description/meshes/cgo3_camera_remeshed_v1.stl" scale="0.001 0.001 0.001"/>
      </geometry>
    </visual>
  </link>
  <link name="typhoon_h480__left_leg">
    <inertial>
      <mass value="0.1"/>
      <origin xyz="0      -0.14313 -0.20725" rpy="0 0 0"/>
      <inertia ixx="0.001" ixy="0" ixz="0" iyy="0.001" iyz="0" izz="0.001"/>
    </inertial>
    <collision name="typhoon_h480__collision">
      <origin xyz="-0.00526 -0.10262 -0.15925" rpy="0      1.56893 0"/>
      <geometry>
        <cylinder radius="0.012209" length="0.3"/>
      </geometry>
    </collision>
    <collision name="typhoon_h480__collision_bar">
      <origin xyz="0.00025 -0.04451 -0.07318" rpy="-0.50131  0       0"/>
      <geometry>
        <cylinder radius="0.00914984" length="0.176893"/>
      </geometry>
    </collision>
    <visual name="base_link_left_leg">
      <origin xyz="-0.00025  0.04051  0.048" rpy="0 0 0"/>
      <geometry>
        <mesh filename="package://drone_nav/description/meshes/leg2_remeshed_v3.stl" scale="0.001 0.001 0.001"/>
      </geometry>
    </visual>
  </link>
  <link name="typhoon_h480__right_leg">
    <inertial>
      <mass value="0.1"/>
      <origin xyz="0       0.14313 -0.20725" rpy="0 0 0"/>
      <inertia ixx="0.001" ixy="0" ixz="0" iyy="0.001" iyz="0" izz="0.001"/>
    </inertial>
    <collision name="typhoon_h480__collision">
      <origin xyz="-0.00526  0.10262 -0.15925" rpy="0      1.56893 0"/>
      <geometry>
        <cylinder radius="0.012209" length="0.3"/>
      </geometry>
    </collision>
    <collision name="typhoon_h480__collision_bar">
      <origin xyz="0.00025  0.04451 -0.07318" rpy="0.50131 0      0"/>
      <geometry>
        <cylinder radius="0.00914984" length="0.176893"/>
      </geometry>
    </collision>
    <visual name="base_link_right_leg">
      <origin xyz="-0.00025 -0.04051  0.048" rpy="0 0 0"/>
      <geometry>
        <mesh filename="package://drone_nav/description/meshes/leg1_remeshed_v3.stl" scale="0.001 0.001 0.001"/>
      </geometry>
    </visual>
  </link>
  <link name="imu_link">
    <inertial>
      <mass value="0.015"/>
      <origin xyz="0 0 0" rpy="0 0 0"/>
      <inertia ixx="1e-05" ixy="0" ixz="0" iyy="1e-05" iyz="0" izz="1e-05"/>
    </inertial>
  </link>
  <link name="lidar_link">
    <inertial>
      <mass value="0.114"/>
      <origin xyz="0.06 0   0.06" rpy="0 0 0"/>
      <inertia ixx="0.001" ixy="0.000" ixz="0.000" iyy="0.001" iyz="0.000" izz="0.001"/>
    </inertial>
    <collision name="typhoon_h480__lidar_collision">
      <origin xyz="0.06 0   0.06" rpy="0 0 0"/>
      <geometry>
        <cylinder radius="0.0508" length="0.07"/>
      </geometry>
    </collision>
    <visual name="typhoon_h480__lidar_visual">
      <origin xyz="0.02 0   0.04" rpy="0 0 0"/>
      <geometry>
        <cylinder radius="0.0508" length="0.08"/>
      </geometry>
    </visual>
  </link>
  <link name="gps_link">
    <inertial>
      <mass value="0.015"/>
      <origin xyz="0 0 0" rpy="0 0 0"/>
      <inertia ixx="1e-05" ixy="0" ixz="0" iyy="1e-05" iyz="0" izz="1e-05"/>
    </inertial>
    <visual name="typhoon_h480__visual">
      <origin xyz="0 0 0" rpy="0 0 0"/>
      <geometry>
        <cylinder radius="0.01" length="0.002"/>
      </geometry>
    </visual>
  </link>
  <link name="typhoon_h480__rotor_3">
    <inertial>
      <mass value="0.005"/>
      <origin xyz="0 0 0" rpy="0 0 0"/>
      <inertia ixx="9.75e-07" ixy="0" ixz="0" iyy="0.000273104" iyz="0" izz="0.000274004"/>
    </inertial>
    <collision name="typhoon_h480__rotor_3_collision">
      <origin xyz="0 0 0" rpy="0 0 0"/>
      <geometry>
        <cylinder radius="0.128" length="0.005"/>
      </geometry>
    </collision>
    <visual name="typhoon_h480__rotor_3_visual">
      <origin xyz="-0.21139 -0.11976 -0.08221" rpy="0 0 0"/>
      <geometry>
        <mesh filename="package://drone_nav/description/meshes/prop_ccw_assembly_remeshed_v3.stl" scale="0.001 0.001 0.001"/>
      </geometry>
    </visual>
  </link>
  <link name="typhoon_h480__rotor_0">
    <inertial>
      <mass value="0.005"/>
      <origin xyz="0 0 0" rpy="0 0 0"/>
      <inertia ixx="9.75e-07" ixy="0" ixz="0" iyy="0.000273104" iyz="0" izz="0.000274004"/>
    </inertial>
    <collision name="typhoon_h480__rotor_0_collision">
      <origin xyz="0 0 0" rpy="0 0 0"/>
      <geometry>
        <cylinder radius="0.128" length="0.005"/>
      </geometry>
    </collision>
    <visual name="typhoon_h480__rotor_0_visual">
      <origin xyz="-0.21139 -0.11976 -0.08221" rpy="0 0 0"/>
      <geometry>
        <mesh filename="package://drone_nav/description/meshes/prop_ccw_assembly_remeshed_v3.stl" scale="0.001 0.001 0.001"/>
      </geometry>
    </visual>
  </link>
  <link name="typhoon_h480__rotor_4">
    <inertial>
      <mass value="0.005"/>
      <origin xyz="0 0 0" rpy="0 0 0"/>
      <inertia ixx="9.75e-07" ixy="0" ixz="0" iyy="0.000273104" iyz="0" izz="0.000274004"/>
    </inertial>
    <collision name="typhoon_h480__rotor_4_collision">
      <origin xyz="0 0 0" rpy="0 0 0"/>
      <geometry>
        <cylinder radius="0.128" length="0.005"/>
      </geometry>
    </collision>
    <visual name="typhoon_h480__rotor_4_visual">
      <origin xyz="0.00187 -0.2427  -0.08221" rpy="0 0 0"/>
      <geometry>
        <mesh filename="package://drone_nav/description/meshes/prop_cw_assembly_remeshed_v3.stl" scale="0.001 0.001 0.001"/>
      </geometry>
    </visual>
  </link>
  <link name="typhoon_h480__rotor_1">
    <inertial>
      <mass value="0.005"/>
      <origin xyz="0 0 0" rpy="0 0 0"/>
      <inertia ixx="9.75e-07" ixy="0" ixz="0" iyy="0.000273104" iyz="0" izz="0.000274004"/>
    </inertial>
    <collision name="typhoon_h480__rotor_1_collision">
      <origin xyz="0 0 0" rpy="0 0 0"/>
      <geometry>
        <cylinder radius="0.128" length="0.005"/>
      </geometry>
    </collision>
    <visual name="typhoon_h480__rotor_1_visual">
      <origin xyz="0.00187 -0.2427  -0.08221" rpy="0 0 0"/>
      <geometry>
        <mesh filename="package://drone_nav/description/meshes/prop_cw_assembly_remeshed_v3.stl" scale="0.001 0.001 0.001"/>
      </geometry>
    </visual>
  </link>
  <link name="typhoon_h480__rotor_5">
    <inertial>
      <mass value="0.005"/>
      <origin xyz="0 0 0" rpy="0 0 0"/>
      <inertia ixx="9.75e-07" ixy="0" ixz="0" iyy="0.000273104" iyz="0" izz="0.000274004"/>
    </inertial>
    <collision name="typhoon_h480__rotor_5_collision">
      <origin xyz="0 0 0" rpy="0 0 0"/>
      <geometry>
        <cylinder radius="0.128" length="0.005"/>
      </geometry>
    </collision>
    <visual name="typhoon_h480__rotor_5_visual">
      <origin xyz="-0.21139 -0.11976 -0.08221" rpy="0 0 0"/>
      <geometry>
        <mesh filename="package://drone_nav/description/meshes/prop_ccw_assembly_remeshed_v3.stl" scale="0.001 0.001 0.001"/>
      </geometry>
    </visual>
  </link>
  <link name="typhoon_h480__rotor_2">
    <inertial>
      <mass value="0.005"/>
      <origin xyz="0 0 0" rpy="0 0 0"/>
      <inertia ixx="9.75e-07" ixy="0" ixz="0" iyy="0.000273104" iyz="0" izz="0.000274004"/>
    </inertial>
    <collision name="typhoon_h480__rotor_2_collision">
      <origin xyz="0 0 0" rpy="0 0 0"/>
      <geometry>
        <cylinder radius="0.128" length="0.005"/>
      </geometry>
    </collision>
    <visual name="typhoon_h480__rotor_2_visual">
      <origin xyz="0.00187 -0.2427  -0.08221" rpy="0 0 0"/>
      <geometry>
        <mesh filename="package://drone_nav/description/meshes/prop_cw_assembly_remeshed_v3.stl" scale="0.001 0.001 0.001"/>
      </geometry>
    </visual>
  </link>
</robot>